Workbook

Sheet Production Dashboard
B2: SAMPLE FEEDS & CO.
B3: MANAGING DIRECTOR DASHBOARD — MONTHLY PERFORMANCE SUMMARY
B4: ='Data Entry Sheet'!$F$5
B6: COMPANY-WIDE SUMMARY (UNIT 1 + UNIT 2)
B8: TOTAL ACTUAL PRODUCTION (MT) | D8: TOTAL HOLIDAY HRS | E8: TOTAL TARGET (MT) | G8: ACHIEVEMENT % | I8: TOTAL SALES (₹) | K8: TOTAL DOWNTIME (Hrs)
B9: =C38+E58 | D9: ='Data Entry Sheet'!F6 | E9: ='Data Entry Sheet'!$F$9+'Data Entry Sheet'!$F$10 | G9: =IFERROR(B9/E9,0) | I9: =SUM('Data Entry Sheet'!$S$19:$S$49) | K9: ='Data Entry Sheet'!I52
B11: COMPANY OEE / AVAILABILITY %
B12: =IFERROR((((COUNT('Data Entry Sheet'!$A$19:$A$49)*'Data Entry Sheet'!$F$7)+(COUNT('Data Entry Sheet'!$A$19:$A$49)*'Data Entry Sheet'!$F$8))-K9)/((COUNT('Data Entry Sheet'!$A$19:$A$49)*'Data Entry Sheet'!$F$7)+(COUNT('Data Entry Sheet'!$A$19:$A$49)*'Data Entry Sheet'!$F$8)),0)
B14: STOCK, EXPENSES & PURCHASE ORDERS
B16: FG STOCK POULTRY (MT) | D16: FG STOCK CATTLE (MT) | E16: RM STOCK (MT) | G16: OFFICE EXPENSES (₹) | I16: PO's - MECHANICAL | K16: PO's - SPARES
B17: ='Data Entry Sheet'!$F$11 | D17: ='Data Entry Sheet'!F12 | E17: ='Data Entry Sheet'!F13 | G17: =SUM('Data Entry Sheet'!$T$19:$T$49) | I17: =SUM('Data Entry Sheet'!$U$19:$U$49) | K17: =SUM('Data Entry Sheet'!$V$19:$V$49)
B19: TOTAL PO's RAISED
B20: =I17+K17
B22: POWER CONSUMPTION BREAKDOWN
B24: SOLAR UNITS (kWh) | E24: EB UNITS (kWh) | G24: GRID UNITS (kWh) | I24: TOTAL POWER (kWh) | N24: Source | O24: kWh
B25: =SUM('Data Entry Sheet'!$W$19:$W$49) | E25: =SUM('Data Entry Sheet'!$X$19:$X$49) | G25: =SUM('Data Entry Sheet'!$Y$19:$Y$49) | I25: =B25+E25+G25 | N25: Solar | O25: =B25
N26: EB | O26: =E25
N27: Grid | O27: =G25
B30: UNIT 1 — BRAND A POULTRY & CATTLE (OWN PRODUCTION + 3RD PARTY JOB WORK)
B32: Production Line | C32: Actual (MT) | E32: Share of Unit 1 %
B33: Brand A - Poultry | C33: ='Data Entry Sheet'!B50 | E33: =IFERROR(C33/$C$38,0)
B34: Brand A - Cattle | C34: ='Data Entry Sheet'!C50 | E34: =IFERROR(C34/$C$38,0)
B35: Brand B | C35: =('Data Entry Sheet'!D50+'Data Entry Sheet'!E50) | E35: =IFERROR(C35/$C$38,0)
B36: Brand C | C36: ='Data Entry Sheet'!F50 | E36: =IFERROR(C36/$C$38,0)
B37: Others | C37: ='Data Entry Sheet'!G50 | E37: =IFERROR(C37/$C$38,0)
B38: UNIT 1 TOTAL | C38: =SUM(C33:C37) | E38: =IFERROR(C38/C38,0)
B40: UNIT 1 TARGET (MT) | E40: UNIT 1 ACTUAL (MT) | G40: UNIT 1 ACHIEVEMENT %
B41: ='Data Entry Sheet'!$F$9 | E41: =C38 | G41: =IFERROR(E41/B41,0)
B43: UNIT 1 DOWNTIME BY REASON
B44: Reason | C44: Hours
B45: Product Change | C45: =SUM('Data Entry Sheet'!$H$19:$H$49)/60
B46: Die Change | C46: =SUM('Data Entry Sheet'!$I$19:$I$49)/60
B47: Breakdown | C47: =SUM('Data Entry Sheet'!$K$19:$K$49)/60
B48: Others | C48: =SUM('Data Entry Sheet'!$L$19:$L$49)/60
B49: TOTAL | C49: =SUM(C45:C48)
B51: UNIT 1 DOWNTIME (Hrs) | E51: UNIT 1 OEE / AVAILABILITY %
B52: =K9 | E52: =IFERROR(((COUNT('Data Entry Sheet'!$A$19:$A$49)*'Data Entry Sheet'!$F$7)-C49)/(COUNT('Data Entry Sheet'!$A$19:$A$49)*'Data Entry Sheet'!$F$7),0)
B55: UNIT 2
B57: TARGET (MT) | E57: ACTUAL (MT) | G57: ACHIEVEMENT %
B58: ='Data Entry Sheet'!$F$10 | E58: =SUM('Data Entry Sheet'!$N$19:$N$49) | G58: =IFERROR(E58/B58,0)
...

Sheet Inventory & Transport Dashboard
A1: Sample Feeds & Co. | Inventory & Transport Dashboard
A2: Daily snapshot - vehicle movement, own fleet, FG dispatch, RM receipt, and critical alerts
F3: Report Date: | G3: 46037
A5: TOTAL VEHICLES INWARD | C5: TOTAL VEHICLES OUTWARD | E5: FG DISPATCHED (MT) | G5: RM RECEIVED (MT)
A6: =SUM('RM Sheet'!J6:J67) | C6: =SUM('FG Sheet'!L6:L67) | E6: =SUM('FG Sheet'!M6:M67) | G6: =SUM('RM Sheet'!K6:K67)
A9: OWN FLEET - IN TRANSIT | C9: OWN FLEET - IDLE | E9: RM MATERIALS IN SHORTAGE | G9: FG PRODUCTS STOCKED OUT
A10: =COUNTIF('Transport Sheet'!$E$7:$E$9,"In-Transit") | C10: =COUNTIF('Transport Sheet'!$E$7:$E$9,"Idle") | E10: =COUNTIF($E$41:$E$49,"SHORTAGE") | G10: =COUNTIF($D$53:$D$60,"STOCK OUT")
A14: Company-wise Breakdown
A15: Company | B15: Vehicles Inward | C15: Vehicles Outward | D15: FG Dispatched (MT) | E15: RM Received (MT)
A16: Brand A | B16: =SUM('RM Sheet'!B6:B67) | C16: =SUM('FG Sheet'!D6:D67) | D16: =SUM('FG Sheet'!E6:E67) | E16: =SUM('RM Sheet'!C6:C67)
A17: Brand B | B17: =SUM('RM Sheet'!D6:D67) | C17: =SUM('FG Sheet'!F6:F67) | D17: =SUM('FG Sheet'!G6:G67) | E17: =SUM('RM Sheet'!E6:E67)
A18: Brand C | B18: =SUM('RM Sheet'!F6:F67) | C18: =SUM('FG Sheet'!H6:H67) | D18: =SUM('FG Sheet'!I6:I67) | E18: =SUM('RM Sheet'!G6:G67)
A19: Others | B19: =SUM('RM Sheet'!H6:H67) | C19: =SUM('FG Sheet'!J6:J67) | D19: =SUM('FG Sheet'!K6:K67) | E19: =SUM('RM Sheet'!I6:I67)
A22: Own Vehicle Quick View
A23: Vehicle No | B23: Trip Status | C23: Current Location | D23: Next Schedule
A24: ='Transport Sheet'!A7 | B24: ='Transport Sheet'!E7 | C24: ='Transport Sheet'!D7 | D24: ='Transport Sheet'!F7
A25: ='Transport Sheet'!A8 | B25: ='Transport Sheet'!E8 | C25: ='Transport Sheet'!D8 | D25: ='Transport Sheet'!F8
A26: ='Transport Sheet'!A9 | B26: ='Transport Sheet'!E9 | C26: ='Transport Sheet'!D9 | D26: ='Transport Sheet'!F9
A29: Critical Alerts Quick View
A30: Type | B30: Item | C30: Detail | D30: Status
A31: RM Shortage | B31: =A41 | C31: ="Stock: "&B41&" MT | Need: "&C41&" MT" | D31: =E41
A32: RM Shortage | B32: =A42 | C32: ="Stock: "&B42&" MT | Need: "&C42&" MT" | D32: =E42
A33: RM Shortage | B33: =A43 | C33: ="Stock: "&B43&" MT | Need: "&C43&" MT" | D33: =E43
A34: FG Stock | B34: =A53 | C34: ="Stock: "&B53&" MT | Orders: "&C53&" MT" | D34: =D53
A35: FG Stock | B35: =A54 | C35: ="Stock: "&B54&" MT | Orders: "&C54&" MT" | D35: =D54
A37: Legend: | B37: Blue text = cells to fill in daily
A39: RM Shortage Tracker — fill in daily
A40: Material Name | B40: Current Stock (MT) | C40: Min Required (MT) | D40: Shortage (MT) | E40: Status
A41: =Shortage!A3 | B41: =Shortage!B3 | C41: =Shortage!C3 | D41: =MAX(C41-B41,0) | E41: =IF(AND(B41<>"",C41<>""),IF(B41<C41,"SHORTAGE","OK"),"")
A42: =Shortage!A4 | B42: =Shortage!B4 | C42: =Shortage!C4 | D42: =MAX(C42-B42,0) | E42: =IF(AND(B42<>"",C42<>""),IF(B42<C42,"SHORTAGE","OK"),"")
A43: =Shortage!A5 | B43: =Shortage!B5 | C43: =Shortage!C5 | D43: =MAX(C43-B43,0) | E43: =IF(AND(B43<>"",C43<>""),IF(B43<C43,"SHORTAGE","OK"),"")
A44: =Shortage!A6 | B44: =Shortage!B6 | C44: =Shortage!C6 | D44: =MAX(C44-B44,0) | E44: =IF(AND(B44<>"",C44<>""),IF(B44<C44,"SHORTAGE","OK"),"")
A45: =Shortage!A7 | B45: =Shortage!B7 | C45: =Shortage!C7 | D45: =MAX(C45-B45,0) | E45: =IF(AND(B45<>"",C45<>""),IF(B45<C45,"SHORTAGE","OK"),"")
A46: =Shortage!A8 | B46: =Shortage!B8 | C46: =Shortage!C8 | D46: =MAX(C46-B46,0) | E46: =IF(AND(B46<>"",C46<>""),IF(B46<C46,"SHORTAGE","OK"),"")
A47: =Shortage!A9 | B47: =Shortage!B9 | C47: =Shortage!C9 | D47: =MAX(C47-B47,0) | E47: =IF(AND(B47<>"",C47<>""),IF(B47<C47,"SHORTAGE","OK"),"")
A48: =Shortage!A10 | B48: =Shortage!B10 | C48: =Shortage!C10 | D48: =MAX(C48-B48,0) | E48: =IF(AND(B48<>"",C48<>""),IF(B48<C48,"SHORTAGE","OK"),"")
A49: =Shortage!A11 | B49: =Shortage!B11 | C49: =Shortage!C11 | D49: =MAX(C49-B49,0) | E49: =IF(AND(B49<>"",C49<>""),IF(B49<C49,"SHORTAGE","OK"),"")
A51: FG Stock-Out Tracker — fill in daily
A52: Product | B52: Current Stock (MT) | C52: Active Orders (MT) | D52: Status
A53: =Shortage!A15 | B53: =Shortage!B15 | C53: =Shortage!C15 | D53: =IF(B53<>"",IF(B53<=0,"STOCK OUT","OK"),"")
...

Sheet Data Entry Sheet
A1: SAMPLE FEEDS & CO. — DAILY DATA ENTRY SHEET
A2: Fill in the yellow cells only (one row per day). The MD Dashboard updates automatically.
A4: MONTHLY SETUP
A5: Reporting Month | F5: 46023
A6: Planned leave for month hrs | F6: 24
A7: Unit 1 — Planned Run Hours / Day | F7: 24
A8: Unit 2 — Planned Run Hours / Day | F8: 12
A9: Unit 1 — Production Target (MT) [single overall target — not split by product] | F9: 5000
A10: Unit 2 — Production Target (MT) | F10: 150
A11: Current FG Stock POULTRY (MT) | F11: ='FG Sheet'!B3
A12: Current FG Stock CATTLE (MT) | F12: ='FG Sheet'!E3
A13: Current RM Stock (MT) | F13: ='RM Sheet'!B3
A14: Note: OEE = Availability % = (Planned Run Hours − Downtime) ÷ Planned Run Hours. Targets are tracked as a single overall figure per unit (not split by product). Sales are tracked as one company total (not split by unit). Downtime is tracked by reason (Product Change / Die Change / Breakdown / Others), not as one lump figure. Purchase Orders are tracked as Mechanical or Spares.
A16: DAILY LOG — ONE ROW PER DAY (all units + utilities together)
B17: UNIT 1 — BRAND A POULTRY & CATTLE (PRODUCTION, MT) | H17: UNIT 1 DOWNTIME BY REASON (Hrs) | M17: UNIT 2 | O17: UNIT 2 DOWNTIME BY REASON (Hrs) | S17: SALES, EXPENSES & PURCHASE ORDERS | W17: ELECTRICAL / POWER (kWh)
A18: Date | B18: Brand A - Poultry (MT) | C18: Brand A - Cattle (MT) | D18: Brand B - Poultry (MT) | E18: Brand B - Cattle (MT) | F18: Brand C (MT) | G18: Others (MT) | H18: Product Change (Hrs) | I18: Die Change (Hrs) | J18: Power Cut | K18: Breakdown (Hrs) | L18: Others (Hrs) | M18: Brand A (MT) | N18: Brand C (MT) | O18: Product Change (Hrs) | P18: Die Change (Hrs) | Q18: Breakdown (Hrs) | R18: Others (Hrs) | S18: Total Sales (₹) | T18: Office Expense (₹) | U18: PO - Mechanical (Count) | V18: PO - RM (Count) | W18: Solar Units (kWh) | X18: EB Units (kWh) | Y18: Grid Units (kWh)
A19: 46204 | B19: 42 | D19: 58.8 | H19: =30/60 | L19: =20/60 | U19: 1
A20: 46205 | D20: 98.8 | J20: =120/60
A21: 46206
A22: 46207 | D22: 80.4 | F22: 95.9 | H22: 0 | J22: =10/60
A23: 46208 | B23: 35.3 | D23: 59.3 | F23: 55.8 | H23: =120/60 | L23: =60/60
A24: 46209 | D24: 127.2 | H24: =30/60 | J24: 0
A25: 46210 | B25: =15/60 | C25: 29.4 | D25: 169.1 | F25: 48 | H25: =45/60 | L25: =60/60
A26: 46211 | C26: 8.4 | G26: 5 | H26: =30/60 | L26: 1.09
A27: 46212 | C27: 23.8 | G27: 6 | H27: =10/60 | L27: =120/60
A28: 46213 | B28: 24.7 | C28: 27 | F28: 179.4 | G28: 5 | H28: =20/60 | I28: 0.09 | J28: =20/60 | L28: =30/60
A29: 46214
A30: 46215
A31: 46216
A32: 46217
A33: 46218
A34: 46219
A35: 46220
A36: 46221
A37: 46222
A38: 46223
A39: 46224
A40: 46225
... A49: 46234
B50: =SUM(B19:B49) | C50: =SUM(C19:C49) | D50: =SUM(D19:D49) | E50: =SUM(E19:E49) | F50: =SUM(F20:F49) | G50: =SUM(G19:G49) | H50: =SUM(H19:H49) | I50: =SUM(I19:I49) | K50: =SUM(K19:K49) | L50: =SUM(L19:L49) | M50: =SUM(M19:M49) | N50: =SUM(N19:N49)
...

Sheet Transport Sheet
A1: Sample Feeds & Co. | Own Fleet — Live Status
A2: Live status of the 3 company-owned vehicles.
A4: OWN FLEET — LIVE STATUS (3 Company Vehicles)
A6: Vehicle No | B6: Driver Name | C6: Driver Phone | D6: Current Location | E6: Trip Status | F6: Next Schedule | G6: Last Updated | H6: Remarks
E7: Idle
E8: Idle
E9: Unloading
A11: Legend: | B11: Blue text = cells to fill in daily
A13: Fleet Status Overview
A14: Status | B14: Vehicle Count
A15: In-Transit | B15: =COUNTIF($E$7:$E$9,A15)
A16: Loading | B16: =COUNTIF($E$7:$E$9,A16)
A17: Unloading | B17: =COUNTIF($E$7:$E$9,A17)
A18: Idle | B18: =COUNTIF($E$7:$E$9,A18)

Sheet FG Sheet
A1: Sample Feeds & Co. | Finished Goods (FG) Dispatch Log
A2: One row per day — vehicles and tons dispatched, company-wise.
A3: Total Poultry stock = | D3: Total Cattle Stock = | F3: Fill in daily
A4: Date | B4: Brand A Poultry | D4: Brand A Cattle | F4: Brand B | H4: Brand C | J4: Others | L4: Total Vehicles | M4: Total Dispatched (MT)
B5: Vehicles count | C5: Dispatched (MT) | D5: Vehicles count | E5: Dispatched (MT) | F5: Vehicles count | G5: Dispatched (MT) | H5: Vehicles count | I5: Dispatched (MT) | J5: Vehicles count | K5: Dispatched (MT)
A6: 46235 | L6: =D6+F6+H6+J6 | M6: =E6+G6+I6+K6
A7: 46236 | L7: =D7+F7+H7+J7 | M7: =E7+G7+I7+K7
A8: 46237 | L8: =D8+F8+H8+J8 | M8: =E8+G8+I8+K8
A9: 46238 | L9: =D9+F9+H9+J9 | M9: =E9+G9+I9+K9
A10: 46239 | L10: =D10+F10+H10+J10 | M10: =E10+G10+I10+K10
A11: 46240 | L11: =D11+F11+H11+J11 | M11: =E11+G11+I11+K11
A12: 46241 | L12: =D12+F12+H12+J12 | M12: =E12+G12+I12+K12
A13: 46242 | L13: =D13+F13+H13+J13 | M13: =E13+G13+I13+K13
A14: 46243 | L14: =D14+F14+H14+J14 | M14: =E14+G14+I14+K14
A15: 46244 | L15: =D15+F15+H15+J15 | M15: =E15+G15+I15+K15
A16: 46245 | L16: =D16+F16+H16+J16 | M16: =E16+G16+I16+K16
A17: 46246 | L17: =D17+F17+H17+J17 | M17: =E17+G17+I17+K17
... A36: 46265 | L36: =D36+F36+H36+J36 | M36: =E36+G36+I36+K36
L37: =D37+F37+H37+J37 | M37: =E37+G37+I37+K37
L38: =D38+F38+H38+J38 | M38: =E38+G38+I38+K38
L39: =D39+F39+H39+J39 | M39: =E39+G39+I39+K39
L40: =D40+F40+H40+J40 | M40: =E40+G40+I40+K40
L41: =D41+F41+H41+J41 | M41: =E41+G41+I41+K41
L42: =D42+F42+H42+J42 | M42: =E42+G42+I42+K42
L43: =D43+F43+H43+J43 | M43: =E43+G43+I43+K43
L44: =D44+F44+H44+J44 | M44: =E44+G44+I44+K44
L45: =D45+F45+H45+J45 | M45: =E45+G45+I45+K45
L46: =D46+F46+H46+J46 | M46: =E46+G46+I46+K46
L47: =D47+F47+H47+J47 | M47: =E47+G47+I47+K47
L48: =D48+F48+H48+J48 | M48: =E48+G48+I48+K48
... L67: =D67+F67+H67+J67 | M67: =E67+G67+I67+K67
A69: Legend: | D69: Blue text = cells to fill in daily; Total columns auto-calculate
A71: MONTH TOTAL | D71: =SUM(D6:D67) | E71: =SUM(E6:E67) | F71: =SUM(F6:F67) | G71: =SUM(G6:G67) | H71: =SUM(H6:H67) | I71: =SUM(I6:I67) | J71: =SUM(J6:J67) | K71: =SUM(K6:K67) | ... M71: =SUM(M6:M67)

Sheet RM Sheet
A1: Sample Feeds & Co. | Raw Material (RM) Receipt Log
A2: One row per day — vehicles and tons received, company-wise.
A3: Total Brand A RM Mt= | B3: =C71
A4: Date | B4: Brand A | D4: Brand B | F4: Brand C | H4: Others | J4: Total Vehicles | K4: Total Received (MT)
B5: Vehicles | C5: Received (MT) | D5: Vehicles | E5: Received (MT) | F5: Vehicles | G5: Received (MT) | H5: Vehicles | I5: Received (MT)
A6: 46235 | J6: =B6+D6+F6+H6 | K6: =C6+E6+G6+I6
A7: 46236 | J7: =B7+D7+F7+H7 | K7: =C7+E7+G7+I7
A8: 46237 | J8: =B8+D8+F8+H8 | K8: =C8+E8+G8+I8
A9: 46238 | J9: =B9+D9+F9+H9 | K9: =C9+E9+G9+I9
A10: 46239 | J10: =B10+D10+F10+H10 | K10: =C10+E10+G10+I10
A11: 46240 | J11: =B11+D11+F11+H11 | K11: =C11+E11+G11+I11
A12: 46241 | J12: =B12+D12+F12+H12 | K12: =C12+E12+G12+I12
A13: 46242 | J13: =B13+D13+F13+H13 | K13: =C13+E13+G13+I13
A14: 46243 | J14: =B14+D14+F14+H14 | K14: =C14+E14+G14+I14
A15: 46244 | J15: =B15+D15+F15+H15 | K15: =C15+E15+G15+I15
A16: 46245 | J16: =B16+D16+F16+H16 | K16: =C16+E16+G16+I16
A17: 46246 | J17: =B17+D17+F17+H17 | K17: =C17+E17+G17+I17
... A36: 46265 | J36: =B36+D36+F36+H36 | K36: =C36+E36+G36+I36
C37: 1 | J37: =B37+D37+F37+H37 | K37: =C37+E37+G37+I37
C38: 2 | J38: =B38+D38+F38+H38 | K38: =C38+E38+G38+I38
C39: 1 | J39: =B39+D39+F39+H39 | K39: =C39+E39+G39+I39
C40: 4 | J40: =B40+D40+F40+H40 | K40: =C40+E40+G40+I40
C41: 3 | J41: =B41+D41+F41+H41 | K41: =C41+E41+G41+I41
C42: 4 | J42: =B42+D42+F42+H42 | K42: =C42+E42+G42+I42
C43: 3 | J43: =B43+D43+F43+H43 | K43: =C43+E43+G43+I43
C44: 2 | J44: =B44+D44+F44+H44 | K44: =C44+E44+G44+I44
C45: 3 | J45: =B45+D45+F45+H45 | K45: =C45+E45+G45+I45
C46: 3 | J46: =B46+D46+F46+H46 | K46: =C46+E46+G46+I46
C47: 2 | J47: =B47+D47+F47+H47 | K47: =C47+E47+G47+I47
C48: 3 | J48: =B48+D48+F48+H48 | K48: =C48+E48+G48+I48
... C67: 2 | J67: =B67+D67+F67+H67 | K67: =C67+E67+G67+I67
A69: Legend: | B69: Blue text = cells to fill in daily; Total columns auto-calculate
A71: MONTH TOTAL | B71: =SUM(B6:B67) | C71: =SUM(C6:C36) | D71: =SUM(D6:D67) | E71: =SUM(E6:E67) | F71: =SUM(F6:F67) | G71: =SUM(G6:G67) | H71: =SUM(H6:H67) | I71: =SUM(I6:I67) | J71: =SUM(J6:J67) | K71: =SUM(K6:K67)

Sheet Shortage
A1: RM Shortage Tracker — fill in daily
A2: Material Name | B2: Current Stock (MT) | C2: Min Required (MT) | D2: Shortage (MT) | E2: Status
A3: Maize | B3: 120 | C3: 100 | D3: =MAX(C3-B3,0) | E3: =IF(AND(B3<>"",C3<>""),IF(B3<C3,"SHORTAGE","OK"),"")
A4: Soya DOC | B4: 80 | C4: 90 | D4: =MAX(C4-B4,0) | E4: =IF(AND(B4<>"",C4<>""),IF(B4<C4,"SHORTAGE","OK"),"")
A5: Broken Rice | B5: 60 | C5: 50 | D5: =MAX(C5-B5,0) | E5: =IF(AND(B5<>"",C5<>""),IF(B5<C5,"SHORTAGE","OK"),"")
D6: =MAX(C6-B6,0) | E6: =IF(AND(B6<>"",C6<>""),IF(B6<C6,"SHORTAGE","OK"),"")
D7: =MAX(C7-B7,0) | E7: =IF(AND(B7<>"",C7<>""),IF(B7<C7,"SHORTAGE","OK"),"")
D8: =MAX(C8-B8,0) | E8: =IF(AND(B8<>"",C8<>""),IF(B8<C8,"SHORTAGE","OK"),"")
D9: =MAX(C9-B9,0) | E9: =IF(AND(B9<>"",C9<>""),IF(B9<C9,"SHORTAGE","OK"),"")
D10: =MAX(C10-B10,0) | E10: =IF(AND(B10<>"",C10<>""),IF(B10<C10,"SHORTAGE","OK"),"")
D11: =MAX(C11-B11,0) | E11: =IF(AND(B11<>"",C11<>""),IF(B11<C11,"SHORTAGE","OK"),"")
A13: FG Stock-Out Tracker — fill in daily
A14: Product | B14: Current Stock (MT) | C14: Active Orders (MT) | D14: Status
B15: 0 | C15: 0 | D15: =IF(B15<>"",IF(B15<=0,"STOCK OUT","OK"),"")
B16: 0 | C16: 0 | D16: =IF(B16<>"",IF(B16<=0,"STOCK OUT","OK"),"")
D17: =IF(B17<>"",IF(B17<=0,"STOCK OUT","OK"),"")
